<?xml version="1.0"?>
<robot name="roarm_m3">
  <!-- Clean URDF generated from roarm_m3.xacro (no ROS/xacro includes, relative mesh paths) -->

  <!-- Links -->
  <link name="world" />

  <link name="base_link">
    <inertial>
      <origin xyz="-0.0068 0 -0.03" rpy="0 0 0" />
      <mass value="0.2562183" />
      <inertia ixx="0.00029211" ixy="0" ixz="0" iyy="0.00035719" iyz="0" izz="0.000349421" />
    </inertial>
    <visual>
      <origin xyz="0 0 0" rpy="0 0 0"/>
      <geometry>
        <mesh filename="../meshes/roarm_m3/base_link.stl" scale="0.001 0.001 0.001"/>
      </geometry>
    </visual>
    <collision>
      <origin xyz="0 0 0" rpy="0 0 0"/>
      <geometry>
        <mesh filename="../meshes/roarm_m3/base_link.stl" scale="0.001 0.001 0.001"/>
      </geometry>
    </collision>
  </link>

  <link name="link1">
    <inertial>
      <origin xyz="0 0 0.037" rpy="0 0 0" />
      <mass value="0.0729177" />
      <inertia ixx="4.68465E-05" ixy="0" ixz="0" iyy="3.32107E-05" iyz="0" izz="5.01023E-05" />
    </inertial>
    <visual>
      <origin xyz="0 0 0" rpy="0 0 0"/>
      <geometry>
        <mesh filename="../meshes/roarm_m3/link1.stl" scale="0.001 0.001 0.001"/>
      </geometry>
    </visual>
    <collision>
      <origin xyz="0 0 0" rpy="0 0 0"/>
      <geometry>
        <mesh filename="../meshes/roarm_m3/link1.stl" scale="0.001 0.001 0.001"/>
      </geometry>
    </collision>
  </link>

  <link name="link2">
    <inertial>
      <origin xyz="0.119 0.012247 -0.0001" rpy="0 0 0"/>
      <mass value="0.0703216" />
      <inertia ixx="5.46501E-05" ixy="0" ixz="0" iyy="0.000423091" iyz="0" izz="0.000404557" />
    </inertial>
    <visual>
      <origin xyz="0 0 0" rpy="0 0 0"/>
      <geometry>
        <mesh filename="../meshes/roarm_m3/link2.stl" scale="0.001 0.001 0.001"/>
      </geometry>
    </visual>
    <collision>
      <origin xyz="0 0 0" rpy="0 0 0"/>
      <geometry>
        <mesh filename="../meshes/roarm_m3/link2.stl" scale="0.001 0.001 0.001"/>
      </geometry>
    </collision>
  </link>

  <link name="link3">
    <inertial>
      <origin xyz="-0.0015 -0.0765 0.00505" rpy="0 0 0"/>
      <mass value="0.021608"/>
      <inertia ixx="6.37699E-05" iyy="3.67026E-06" izz="6.28965E-05" ixy="0" iyz="0" ixz="0"/>
    </inertial>
    <visual>
      <origin xyz="0 0 0" rpy="0 0 0"/>
      <geometry>
        <mesh filename="../meshes/roarm_m3/link3.stl" scale="0.001 0.001 0.001"/>
      </geometry>
    </visual>
    <collision>
      <origin xyz="0 0 0" rpy="0 0 0"/>
      <geometry>
        <mesh filename="../meshes/roarm_m3/link3.stl" scale="0.001 0.001 0.001"/>
      </geometry>
    </collision>
  </link>

  <link name="link4">
    <inertial>
      <origin xyz="-0.0015 -0.022 -0.00075" rpy="0 0 0"/>
      <mass value="0.0099933"/>
      <inertia ixx="4.53979E-06" iyy="3.78103E-06" izz="5.60238E-06" ixy="-0.0" iyz="-0.0" ixz="0.0"/>
    </inertial>
    <visual>
      <origin xyz="0 0 0" rpy="0 0 0"/>
      <geometry>
        <mesh filename="../meshes/roarm_m3/link4.stl" scale="0.001 0.001 0.001"/>
      </geometry>
    </visual>
    <collision>
      <origin xyz="0 0 0" rpy="0 0 0"/>
      <geometry>
        <mesh filename="../meshes/roarm_m3/link4.stl" scale="0.001 0.001 0.001"/>
      </geometry>
    </collision>
  </link>

  <link name="link5">
    <inertial>
      <origin xyz="-0.0078 0 0.0595" rpy="0 0 0"/>
      <mass value="0.0153928"/>
      <inertia ixx="2.02869E-05" iyy="2.14427E-05" izz="4.39495E-06" ixy="-0.0" iyz="0" ixz="0"/>
    </inertial>
    <visual>
      <origin xyz="0 0 0" rpy="0 0 0"/>
      <geometry>
        <mesh filename="../meshes/roarm_m3/link5.stl" scale="0.001 0.001 0.001"/>
      </geometry>
    </visual>
    <collision>
      <origin xyz="0 0 0" rpy="0 0 0"/>
      <geometry>
        <mesh filename="../meshes/roarm_m3/link5.stl" scale="0.001 0.001 0.001"/>
      </geometry>
    </collision>
  </link>

  <link name="gripper_link">
    <inertial>
      <origin xyz="0.027 0.0027 -0.018935" rpy="0 0 0"/>
      <mass value="0.0028708" />
      <inertia ixx="5.23216E-07" ixy="0" ixz="0" iyy="1.82071E-06" iyz="0" izz="1.60231E-06" />
    </inertial>
    <visual>
      <origin xyz="0 0 0" rpy="0 0 0"/>
      <geometry>
        <mesh filename="../meshes/roarm_m3/gripper_link.stl" scale="0.001 0.001 0.001"/>
      </geometry>
    </visual>
    <collision>
      <origin xyz="0 0 0" rpy="0 0 0"/>
      <geometry>
        <mesh filename="../meshes/roarm_m3/gripper_link.stl" scale="0.001 0.001 0.001"/>
      </geometry>
    </collision>
  </link>

  <link name="hand_tcp">
    <inertial>
      <origin xyz="0 0 0" rpy="0 0 0"/>
      <mass value="0.0005"/>
      <inertia ixx="2e-08" ixy="0" ixz="0" iyy="2e-08" iyz="0" izz="2e-08"/>
    </inertial>
    <visual>
      <origin xyz="0 0 0" rpy="0 0 0"/>
      <geometry>
        <sphere radius="0.01"/>
      </geometry>
      <material name="tcp_marker">
        <color rgba="1 0.6 0 1"/>
      </material>
    </visual>
    <collision>
      <origin xyz="0 0 0" rpy="0 0 0"/>
      <geometry>
        <sphere radius="0.01"/>
      </geometry>
    </collision>
  </link>

  <!-- Joints -->
  <joint name="world_to_base_link" type="fixed">
    <origin xyz="0.0 0.0 0.0701" rpy="0 0 0"/>
    <parent link="world"/>
    <child link="base_link"/>
    <axis xyz="0.0 0.0 1.0"/>
  </joint>

  <joint name="base_link_to_link1" type="revolute">
    <origin xyz="0.0 0.0 0.0" rpy="0 0 0"/>
    <parent link="base_link"/>
    <child link="link1"/>
    <axis xyz="0.0 0.0 1.0"/>
    <limit lower="-1.5708" upper="1.5708" effort="6.0" velocity="4.0" />
    <dynamics damping="0.35" friction="0.05"/>
  </joint>

  <joint name="link1_to_link2" type="revolute">
    <origin xyz="0.0 0.0 0.051959" rpy="-1.5708 -1.5708 0"/>
    <parent link="link1"/>
    <child link="link2"/>
    <axis xyz="-0.0 0 1.0"/>
    <limit lower="-1.5708" upper="1.5708" effort="6.0" velocity="3.5" />
    <dynamics damping="0.4" friction="0.06"/>
  </joint>

  <joint name="link2_to_link3" type="revolute">
    <origin xyz="0.236815 0.030002 0" rpy="0 0 1.5708"/>
    <parent link="link2"/>
    <child link="link3"/>
    <axis xyz="0.0 0.0 1.0"/>
    <limit lower="-1.0" upper="2.95" effort="5.0" velocity="3.0" />
    <dynamics damping="0.32" friction="0.05"/>
  </joint>

  <joint name="link3_to_link4" type="revolute">
    <origin xyz="0.0 -0.144586 0" rpy="0 0 0"/>
    <parent link="link3"/>
    <child link="link4"/>
    <axis xyz="0.0 0.0 1.0"/>
    <limit lower="-1.5708" upper="1.5708" effort="4.5" velocity="3.0" />
    <dynamics damping="0.28" friction="0.05"/>
  </joint>

  <joint name="link4_to_link5" type="revolute">
    <origin xyz="0.015147 -0.053653 0" rpy="1.5708 1.5708 0"/>
    <parent link="link4"/>
    <child link="link5"/>
    <axis xyz="0.0 0.0 1.0"/>
    <limit lower="-3.1416" upper="3.1416" effort="3.5" velocity="4.0" />
    <dynamics damping="0.2" friction="0.04"/>
  </joint>

  <joint name="link5_to_gripper_link" type="revolute">
    <origin xyz="0.00 0.018821 0.052035" rpy="-1.5708 -1.5708 0"/>
    <parent link="link5"/>
    <child link="gripper_link"/>
    <axis xyz="0.0 -0.0 1.0"/>
    <limit lower="0.0" upper="1.5" effort="2.5" velocity="2.5" />
    <dynamics damping="0.15" friction="0.03"/>
  </joint>

  <joint name="link5_to_hand_tcp" type="fixed">
    <origin xyz="0 0 0.115428" rpy="1.5708 -1.5708 0"/>
    <parent link="link5"/>
    <child link="hand_tcp"/>
    <axis xyz="0 0 0"/>
  </joint>

  <!-- Transmissions (bus servo mapping from Waveshare reference) -->
  <transmission name="base_transmission">
    <type>transmission_interface/SimpleTransmission</type>
    <joint name="base_link_to_link1">
      <hardwareInterface>PositionJointInterface</hardwareInterface>
    </joint>
    <actuator name="base_servo">
      <hardwareInterface>PositionJointInterface</hardwareInterface>
      <mechanicalReduction>1.0</mechanicalReduction>
    </actuator>
  </transmission>

  <transmission name="shoulder_transmission">
    <type>transmission_interface/SimpleTransmission</type>
    <joint name="link1_to_link2">
      <hardwareInterface>PositionJointInterface</hardwareInterface>
    </joint>
    <actuator name="shoulder_servo">
      <hardwareInterface>PositionJointInterface</hardwareInterface>
      <mechanicalReduction>1.0</mechanicalReduction>
    </actuator>
  </transmission>

  <transmission name="elbow_transmission">
    <type>transmission_interface/SimpleTransmission</type>
    <joint name="link2_to_link3">
      <hardwareInterface>PositionJointInterface</hardwareInterface>
    </joint>
    <actuator name="elbow_servo">
      <hardwareInterface>PositionJointInterface</hardwareInterface>
      <mechanicalReduction>1.0</mechanicalReduction>
    </actuator>
  </transmission>

  <transmission name="wrist_pitch_transmission">
    <type>transmission_interface/SimpleTransmission</type>
    <joint name="link3_to_link4">
      <hardwareInterface>PositionJointInterface</hardwareInterface>
    </joint>
    <actuator name="wrist_pitch_servo">
      <hardwareInterface>PositionJointInterface</hardwareInterface>
      <mechanicalReduction>1.0</mechanicalReduction>
    </actuator>
  </transmission>

  <transmission name="wrist_roll_transmission">
    <type>transmission_interface/SimpleTransmission</type>
    <joint name="link4_to_link5">
      <hardwareInterface>PositionJointInterface</hardwareInterface>
    </joint>
    <actuator name="wrist_roll_servo">
      <hardwareInterface>PositionJointInterface</hardwareInterface>
      <mechanicalReduction>1.0</mechanicalReduction>
    </actuator>
  </transmission>

  <transmission name="gripper_transmission">
    <type>transmission_interface/SimpleTransmission</type>
    <joint name="link5_to_gripper_link">
      <hardwareInterface>PositionJointInterface</hardwareInterface>
    </joint>
    <actuator name="gripper_servo">
      <hardwareInterface>PositionJointInterface</hardwareInterface>
      <mechanicalReduction>1.0</mechanicalReduction>
    </actuator>
  </transmission>

</robot>
